<?xml version="1.0" ?>
<!-- =================================================================================== -->
<!-- |    This document was autogenerated by xacro from snp_psir_demo.urdf.xacro       | -->
<!-- |    EDITING THIS FILE BY HAND IS NOT RECOMMENDED                                 | -->
<!-- =================================================================================== -->
<robot name="snp_psir_description" xmlns:xacro="http://www.ros.org/wiki/xacro">
  <gazebo>
    <plugin filename="libgazebo_ros_control.so" name="gazebo_ros_control">
      <robotNamespace>/prbt</robotNamespace>
    </plugin>
  </gazebo>
  <material name="grey">
    <color rgba="0.8 0.8 0.9 1"/>
  </material>
  <!-- world-->
  <link name="world_frame"/>
  <joint name="world_to_baselink" type="fixed">
    <parent link="world_frame"/>
    <child link="prbt_base_link"/>
  </joint>
  <!-- robot foot link -->
  <link name="prbt_base_link">
    <inertial>
      <origin rpy="0 0 0" xyz="-0.00014 0.02783 0.05093"/>
      <mass value="7.1"/>
      <inertia ixx="0" ixy="0" ixz="0" iyy="0" iyz="0" izz="0"/>
    </inertial>
    <visual>
      <origin rpy="0 0 0" xyz="0 0 0"/>
      <geometry>
        <mesh filename="package://prbt_support/meshes/foot.dae"/>
      </geometry>
    </visual>
    <collision>
      <origin rpy="3.14159265359 0 0" xyz="0 0 0.065"/>
      <geometry>
        <cylinder length="0.13" radius="0.09275"/>
      </geometry>
    </collision>
  </link>
  <!-- arm 1 joint -->
  <joint name="prbt_joint_1" type="revolute">
    <origin rpy="0 0 -3.14159265359" xyz="0 0 0.2604"/>
    <parent link="prbt_base_link"/>
    <child link="prbt_link_1"/>
    <axis xyz="0 0 1"/>
    <limit effort="370" lower="-2.967" upper="2.967" velocity="1.57"/>
    <dynamics damping="15.0" friction="11"/>
  </joint>
  <!-- arm 1 link -->
  <link name="prbt_link_1">
    <inertial>
      <origin rpy="0 0 0" xyz="-0.00014 0.02783 0.05093"/>
      <mass value="7.1"/>
      <inertia ixx="0" ixy="0" ixz="0" iyy="0" iyz="0" izz="0"/>
    </inertial>
    <visual>
      <origin rpy="0 0 0" xyz="0 0 0"/>
      <geometry>
        <mesh filename="package://prbt_support/meshes/link_1.dae"/>
      </geometry>
    </visual>
    <collision>
      <origin rpy="0 0 0" xyz="0 0 -0.08"/>
      <geometry>
        <cylinder length="0.10" radius="0.07"/>
      </geometry>
    </collision>
    <collision>
      <origin rpy="0 0 0" xyz="0 0 0"/>
      <geometry>
        <sphere radius="0.09"/>
      </geometry>
    </collision>
    <collision>
      <origin rpy="0 1.57079632679 1.57079632679" xyz="0 -0.10 0"/>
      <geometry>
        <cylinder length="0.10" radius="0.065"/>
      </geometry>
    </collision>
  </link>
  <!-- joint between arm_1_link and arm_2_link -->
  <joint name="prbt_joint_2" type="revolute">
    <origin rpy="1.57079632679 0 0" xyz="0 0 0"/>
    <parent link="prbt_link_1"/>
    <child link="prbt_link_2"/>
    <axis xyz="0 0 1"/>
    <limit effort="370" lower="-2.531" upper="2.531" velocity="1.57"/>
    <dynamics damping="12.0" friction="10.0"/>
  </joint>
  <link name="prbt_link_2">
    <inertial>
      <origin rpy="0 0 0" xyz="0.00001 0.16907 0.02464"/>
      <mass value="2.4"/>
      <inertia ixx="0" ixy="0" ixz="0" iyy="0" iyz="0" izz="0"/>
    </inertial>
    <visual name="first">
      <origin rpy="0 0 0" xyz="0 0 0"/>
      <geometry>
        <mesh filename="package://prbt_support/meshes/link_2.dae"/>
      </geometry>
    </visual>
    <collision>
      <origin rpy="0.174532925199 0 0" xyz="0 0.15 0.145"/>
      <geometry>
        <box size="0.121 0.27 0.065"/>
      </geometry>
    </collision>
    <collision>
      <origin rpy="-0.448798950513 0 0" xyz="0 0.3 0.145"/>
      <geometry>
        <box size="0.11 0.1 0.075"/>
      </geometry>
    </collision>
  </link>
  <!-- joint between arm_2_link and arm_3_link -->
  <joint name="prbt_joint_3" type="revolute">
    <origin rpy="0 3.14159265359 0" xyz="0 0.35 0"/>
    <parent link="prbt_link_2"/>
    <child link="prbt_link_3"/>
    <axis xyz="0 0 1"/>
    <limit effort="176" lower="-2.356" upper="2.356" velocity="1.57"/>
    <dynamics damping="4.5" friction="4.5"/>
  </joint>
  <link name="prbt_link_3">
    <inertial>
      <origin rpy="0 0 0" xyz="-0.0001 0.04395 -0.02798"/>
      <mass value="5.0"/>
      <inertia ixx="0" ixy="0" ixz="0" iyy="0" iyz="0" izz="0"/>
    </inertial>
    <visual>
      <origin rpy="0 0 0" xyz="0 0 0"/>
      <geometry>
        <mesh filename="package://prbt_support/meshes/link_3.dae"/>
      </geometry>
    </visual>
    <collision>
      <origin rpy="0 0 0" xyz="0 0 -0.11"/>
      <geometry>
        <cylinder length="0.10" radius="0.06"/>
      </geometry>
    </collision>
    <collision>
      <origin rpy="0 0 0" xyz="0 0 0"/>
      <geometry>
        <sphere radius="0.085"/>
      </geometry>
    </collision>
    <collision>
      <origin rpy="0 1.57079632679 1.57079632679" xyz="0 0.10 0"/>
      <geometry>
        <cylinder length="0.10" radius="0.065"/>
      </geometry>
    </collision>
  </link>
  <!-- joint between arm_3_link and arm_4_link -->
  <joint name="prbt_joint_4" type="revolute">
    <origin rpy="-1.57079632679 3.14159265359 0" xyz="0 0 0"/>
    <parent link="prbt_link_3"/>
    <child link="prbt_link_4"/>
    <axis xyz="0 0 1"/>
    <limit effort="176" lower="-2.967" upper="2.967" velocity="1.57"/>
    <dynamics damping="4.2" friction="3.8"/>
  </joint>
  <link name="prbt_link_4">
    <inertial>
      <origin rpy="0 0 0" xyz="-0.00008 0.06528 0.06149"/>
      <mass value="0.7"/>
      <inertia ixx="0" ixy="0" ixz="0" iyy="0" iyz="0" izz="0"/>
    </inertial>
    <visual>
      <origin rpy="0 0 0" xyz="0 0 0"/>
      <geometry>
        <mesh filename="package://prbt_support/meshes/link_4.dae"/>
      </geometry>
    </visual>
    <collision>
      <origin rpy="0.966643893412 0 0" xyz="0 -0.04 0.162"/>
      <geometry>
        <box size="0.121 0.08 0.17"/>
      </geometry>
    </collision>
    <collision>
      <origin rpy="-0.10471975512 0 0" xyz="0 -0.115 0.25"/>
      <geometry>
        <box size="0.09 0.06 0.12"/>
      </geometry>
    </collision>
  </link>
  <!-- joint between arm_4_link and arm_5_link -->
  <joint name="prbt_joint_5" type="revolute">
    <origin rpy="1.57079632679 0 3.14159265359" xyz="0 0 0.307"/>
    <parent link="prbt_link_4"/>
    <child link="prbt_link_5"/>
    <axis xyz="0 0 1"/>
    <limit effort="41.6" lower="-2.967" upper="2.967" velocity="1.57"/>
    <dynamics damping="1.5" friction="3.5"/>
  </joint>
  <link name="prbt_link_5">
    <inertial>
      <origin rpy="0 0 0" xyz="-0.00026 0.01873 -0.03434"/>
      <mass value="2"/>
      <inertia ixx="0" ixy="0" ixz="0" iyy="0" iyz="0" izz="0"/>
    </inertial>
    <visual>
      <origin rpy="0 0 0" xyz="0 0 0"/>
      <geometry>
        <mesh filename="package://prbt_support/meshes/link_5.dae"/>
      </geometry>
    </visual>
    <collision>
      <origin rpy="0 0 0" xyz="0 0 -0.095"/>
      <geometry>
        <cylinder length="0.08" radius="0.045"/>
      </geometry>
    </collision>
    <collision>
      <origin rpy="0 0 0" xyz="0 0 -0.06"/>
      <geometry>
        <cylinder length="0.04" radius="0.0545"/>
      </geometry>
    </collision>
    <collision>
      <origin rpy="0 0 0" xyz="0 0 0"/>
      <geometry>
        <sphere radius="0.07"/>
      </geometry>
    </collision>
    <collision>
      <origin rpy="0 1.57079632679 1.57079632679" xyz="0 0.05 0"/>
      <geometry>
        <cylinder length="0.03" radius="0.05"/>
      </geometry>
    </collision>
    <collision>
      <origin rpy="0 1.57079632679 1.57079632679" xyz="0 0.05 0"/>
      <geometry>
        <cylinder length="0.049" radius="0.0435"/>
      </geometry>
    </collision>
  </link>
  <!-- joint between arm_5_link and flange -->
  <joint name="prbt_joint_6" type="revolute">
    <origin rpy="-1.57079632679 0 0" xyz="0 0.084 0"/>
    <parent link="prbt_link_5"/>
    <child link="prbt_flange"/>
    <axis xyz="0 0 1"/>
    <limit effort="20.1" lower="-3.124" upper="3.124" velocity="1.57"/>
    <dynamics damping="4.5" friction="7.0"/>
  </joint>
  <!-- Flange -->
  <link name="prbt_flange">
    <visual>
      <origin rpy="0 0 0" xyz="0 0 0"/>
      <geometry>
        <mesh filename="package://prbt_support/meshes/flange.dae"/>
      </geometry>
    </visual>
    <collision>
      <origin rpy="0 0 0" xyz="0 0 -0.0035"/>
      <geometry>
        <cylinder length="0.02" radius="0.0331"/>
      </geometry>
    </collision>
  </link>
  <!-- ROS-Industrial 'base' frame: base_link to robot world coordinate sytem transform -->
  <link name="prbt_base"/>
  <joint name="prbt_base_link-base" type="fixed">
    <origin rpy="0 0 0" xyz="0 0 0"/>
    <parent link="prbt_base_link"/>
    <child link="prbt_base"/>
  </joint>
  <!-- ROS-Industrial 'tool0' frame: all-zeros tool frame -->
  <link name="prbt_tool0"/>
  <joint name="prbt_flange-tool0" type="fixed">
    <origin rpy="0 0 0" xyz="0 0 0"/>
    <parent link="prbt_flange"/>
    <child link="prbt_tool0"/>
  </joint>
  <transmission name="prbt_joint_1_trans">
    <type>transmission_interface/SimpleTransmission</type>
    <joint name="prbt_joint_1">
      <hardwareInterface>hardware_interface/PositionJointInterface</hardwareInterface>
    </joint>
    <actuator name="prbt_joint_1_motor">
      <mechanicalReduction>1</mechanicalReduction>
    </actuator>
  </transmission>
  <transmission name="prbt_joint_2_trans">
    <type>transmission_interface/SimpleTransmission</type>
    <joint name="prbt_joint_2">
      <hardwareInterface>hardware_interface/PositionJointInterface</hardwareInterface>
    </joint>
    <actuator name="prbt_joint_2_motor">
      <mechanicalReduction>1</mechanicalReduction>
    </actuator>
  </transmission>
  <transmission name="prbt_joint_3_trans">
    <type>transmission_interface/SimpleTransmission</type>
    <joint name="prbt_joint_3">
      <hardwareInterface>hardware_interface/PositionJointInterface</hardwareInterface>
    </joint>
    <actuator name="prbt_joint_3_motor">
      <mechanicalReduction>1</mechanicalReduction>
    </actuator>
  </transmission>
  <transmission name="prbt_joint_4_trans">
    <type>transmission_interface/SimpleTransmission</type>
    <joint name="prbt_joint_4">
      <hardwareInterface>hardware_interface/PositionJointInterface</hardwareInterface>
    </joint>
    <actuator name="prbt_joint_4_motor">
      <mechanicalReduction>1</mechanicalReduction>
    </actuator>
  </transmission>
  <transmission name="prbt_joint_5_trans">
    <type>transmission_interface/SimpleTransmission</type>
    <joint name="prbt_joint_5">
      <hardwareInterface>hardware_interface/PositionJointInterface</hardwareInterface>
    </joint>
    <actuator name="prbt_joint_5_motor">
      <mechanicalReduction>1</mechanicalReduction>
    </actuator>
  </transmission>
  <transmission name="prbt_joint_6_trans">
    <type>transmission_interface/SimpleTransmission</type>
    <joint name="prbt_joint_6">
      <hardwareInterface>hardware_interface/PositionJointInterface</hardwareInterface>
    </joint>
    <actuator name="prbt_joint_6_motor">
      <mechanicalReduction>1</mechanicalReduction>
    </actuator>
  </transmission>
  <link name="table">
    <collision>
      <!-- rechts -->
      <origin rpy="0 0 0" xyz="0 0.305 0.575"/>
      <geometry>
        <box size="0.6 0.05 1.15"/>
      </geometry>
    </collision>
    <visual>
      <origin rpy="0 0 0" xyz="0 0.305 0.08"/>
      <geometry>
        <box size="0.6 0.05 0.16"/>
      </geometry>
      <material name="grey"/>
    </visual>
    <collision>
      <!-- vorne -->
      <origin rpy="0 0 0" xyz="-0.3 -0.28 0.575"/>
      <geometry>
        <box size="0.05 1.2 1.15"/>
      </geometry>
    </collision>
    <visual>
      <origin rpy="0 0 0" xyz="-0.3 -0.28 0.08"/>
      <geometry>
        <box size="0.05 1.2 0.16"/>
      </geometry>
      <material name="grey"/>
    </visual>
    <collision>
      <!--hinten-->
      <origin rpy="0 0 0" xyz="0.3 -0.28 0.575"/>
      <geometry>
        <box size="0.05 1.2 1.15"/>
      </geometry>
    </collision>
    <visual>
      <origin rpy="0 0 0" xyz="0.3 -0.28 0.08"/>
      <geometry>
        <box size="0.05 1.2 0.16"/>
      </geometry>
      <material name="grey"/>
    </visual>
    <collision>
      <!--links-->
      <origin rpy="0 0 0" xyz="0 -0.895 0.575"/>
      <geometry>
        <box size="0.6 0.05 1.15"/>
      </geometry>
    </collision>
    <visual>
      <origin rpy="0 0 0" xyz="0 -0.895 0.08"/>
      <geometry>
        <box size="0.6 0.05 0.16"/>
      </geometry>
      <material name="grey"/>
    </visual>
    <collision>
      <!-- bottom -->
      <origin rpy="0 0 0" xyz="0 -0.32 0.12"/>
      <geometry>
        <box size="0.6 1.2 0.05"/>
      </geometry>
    </collision>
    <visual>
      <origin rpy="0 0 0" xyz="0 -0.32 0.12"/>
      <geometry>
        <box size="0.6 1.2 0.05"/>
      </geometry>
      <material name="grey"/>
    </visual>
    <collision>
      <!-- top -->
      <origin rpy="0 0 0" xyz="0 -0.32 1.15"/>
      <geometry>
        <box size="0.6 1.2 0.05"/>
      </geometry>
    </collision>
  </link>
  <joint name="table_joint" type="fixed">
    <origin rpy="0 0 0" xyz="0 0 0"/>
    <parent link="world_frame"/>
    <child link="table"/>
  </joint>
  <!-- tool fixture -->
  <link name="tool_fixture">
    <inertial>
      <origin rpy="0 0 0" xyz="0.015 0 0.1"/>
      <mass value="0.5"/>
      <inertia ixx="0.0" ixy="0.0" ixz="0.0" iyy="0.0" iyz="0.0" izz="0.0"/>
    </inertial>
    <visual>
      <origin rpy="0 0 0" xyz="0 0 0"/>
      <geometry>
        <mesh filename="package://snp_psir_description/meshes/tool_fixture.STL"/>
      </geometry>
      <material name="">
        <color rgba="0.75 0.75 0.75 1"/>
      </material>
    </visual>
    <collision>
      <origin rpy="0 0 0" xyz="0 0 0"/>
      <geometry>
        <mesh filename="package://snp_psir_description/meshes/tool_fixture.STL"/>
      </geometry>
    </collision>
  </link>
  <joint name="tool_joint" type="fixed">
    <parent link="prbt_tool0"/>
    <child link="tool_fixture"/>
    <origin rpy="0 0 3.92699081699" xyz="0 0 0"/>
  </joint>
  <link name="acf_111_04_and_grinder">
    <inertial>
      <origin rpy="0 0 0" xyz="0 0 0.145"/>
      <mass value="5"/>
      <inertia ixx="0.02" ixy="0" ixz="0" iyy="0.02" iyz="0" izz="0.02"/>
    </inertial>
    <visual>
      <origin rpy="0 0 0" xyz="0 0 0"/>
      <geometry>
        <mesh filename="package://snp_psir_description/meshes/acf_with_grinder/acf_110_01_xs_with_grinder.STL" scale="0.001 0.001 0.001"/>
      </geometry>
      <material name="">
        <color rgba="0.8 0.8 0.9 1"/>
      </material>
    </visual>
    <collision>
      <origin rpy="0 0 0" xyz="0 0 0.13"/>
      <geometry>
        <cylinder length="0.2487" radius="0.07"/>
      </geometry>
    </collision>
    <!-- Attached cable -->
    <collision>
      <origin rpy="0 1.57079632679 0" xyz="-0.08 0.02 0.035"/>
      <geometry>
        <cylinder length="0.04" radius="0.012"/>
      </geometry>
    </collision>
    <!-- air pumper -->
    <collision>
      <origin rpy="1.57079632679 0 0" xyz="0.0 0.1 0.20"/>
      <geometry>
        <cylinder length="0.08" radius="0.02"/>
      </geometry>
    </collision>
  </link>
  <!--joint between fixture and polisher-->
  <joint name="acf_111_04_joint" type="fixed">
    <origin rpy="0 0 1.57079632679" xyz="0 0 0.018"/>
    <parent link="tool_fixture"/>
    <child link="acf_111_04_and_grinder"/>
    <axis xyz="0 0 0"/>
  </joint>
  <link name="tcp_frame"/>
  <joint name="tip_joint" type="fixed">
    <parent link="acf_111_04_and_grinder"/>
    <child link="tcp_frame"/>
    <origin rpy="0 0 0" xyz="0 0 0.25215"/>
  </joint>
  <!-- for collision cylinder -->
  <link name="polish_disc">
    <visual>
      <origin rpy="0 0 0" xyz="0 0 0.0075"/>
      <geometry>
        <cylinder length="0.015" radius="0.07"/>
      </geometry>
      <material name="">
        <color rgba="1 1 1 1"/>
      </material>
    </visual>
    <collision>
      <origin rpy="0 0 0" xyz="0 0 0.0075"/>
      <geometry>
        <cylinder length="0.015" radius="0.07"/>
      </geometry>
    </collision>
  </link>
  <joint name="polish_disc_joint" type="fixed">
    <origin rpy="0 0 0" xyz="0 0 0.2487"/>
    <parent link="acf_111_04_and_grinder"/>
    <child link="polish_disc"/>
  </joint>
  <link name="tool_stroke">
    <visual>
      <origin rpy="0 0 0" xyz="0 0 0.00575"/>
      <geometry>
        <cylinder length="0.0115" radius="0.07"/>
      </geometry>
      <material name="">
        <color rgba="0.3 0.8 0.3 0.4"/>
      </material>
    </visual>
    <collision>
      <origin rpy="0 0 0" xyz="0 0 0.00575"/>
      <geometry>
        <cylinder length="0.0115" radius="0.07"/>
      </geometry>
    </collision>
  </link>
  <joint name="tool_stroke_joint" type="fixed">
    <origin rpy="0 0 0" xyz="0 0 0.015"/>
    <parent link="polish_disc"/>
    <child link="tool_stroke"/>
  </joint>
  <link name="ensenso">
    <inertial>
      <origin rpy="0 0 0" xyz="-0.0 -0.05 0.02"/>
      <mass value="0.5"/>
      <inertia ixx="0.0" ixy="0.0" ixz="0.0" iyy="0.0" iyz="0.0" izz="0.0"/>
    </inertial>
    <visual>
      <origin rpy="0 0 0" xyz="0 0 0"/>
      <geometry>
        <mesh filename="package://snp_psir_description/meshes/ensenso_n35.STL"/>
      </geometry>
      <material name="">
        <color rgba="0.8 0.8 0.9 1"/>
      </material>
    </visual>
    <collision>
      <origin rpy="0 0 0" xyz="0 0 0.02"/>
      <geometry>
        <box size="0.18 0.05 0.055"/>
      </geometry>
    </collision>
  </link>
  <link name="ensenso_frame"/>
  <joint name="ensenso_mod_joint" type="fixed">
    <origin rpy="0 -1.57079632679 -1.57079632679" xyz="0 0 0.052"/>
    <parent link="ensenso"/>
    <child link="ensenso_frame"/>
    <axis xyz="0 0 0"/>
  </joint>
  <!--Joint between ensenso and fixture-->
  <joint name="ensenso_tool_joint" type="fixed">
    <origin rpy="-1.57079632679 0 -1.57079632679" xyz="0.068 0.003 0.048"/>
    <parent link="tool_fixture"/>
    <child link="ensenso"/>
    <axis xyz="0 0 0"/>
  </joint>
  <!--Frames related to the motion of the camera-->
  <link name="ensenso_sensor_optical_frame">
    <inertial>
      <mass value="0.001"/>
      <origin xyz="0 0 0"/>
      <inertia ixx="0.0001" ixy="0.0" ixz="0.0" iyy="0.0001" iyz="0.0" izz="0.0001"/>
    </inertial>
  </link>
  <joint name="ensenso_joint" type="fixed">
    <parent link="ensenso_frame"/>
    <child link="ensenso_optical_frame"/>
    <origin rpy="-1.57079632679 0 -1.57079632679" xyz="0 0.05 0"/>
  </joint>
  <link name="ensenso_optical_frame">
    <inertial>
      <mass value="0.001"/>
      <origin xyz="0 0 0"/>
      <inertia ixx="0.0001" ixy="0.0" ixz="0.0" iyy="0.0001" iyz="0.0" izz="0.0001"/>
    </inertial>
  </link>
  <joint name="ensenso_joint_sim" type="fixed">
    <parent link="ensenso_frame"/>
    <child link="ensenso_optical_frame_sim"/>
    <origin rpy="-1.57079632679 0 -1.57079632679" xyz="0 0.0 0"/>
  </joint>
  <link name="ensenso_optical_frame_sim">
    <inertial>
      <mass value="0.001"/>
      <origin xyz="0 0 0"/>
      <inertia ixx="0.0001" ixy="0.0" ixz="0.0" iyy="0.0001" iyz="0.0" izz="0.0001"/>
    </inertial>
  </link>
  <joint name="ensenso_optical_joint" type="fixed">
    <parent link="ensenso_optical_frame"/>
    <child link="ensenso_sensor_optical_frame"/>
    <origin rpy="0 0 3.142" xyz="0 0 0"/>
  </joint>
  <link name="ensenso_move_frame"/>
  <joint name="ensenso_move_frame_join" type="fixed">
    <parent link="ensenso_frame"/>
    <child link="ensenso_move_frame"/>
    <origin rpy="1.57079632679 0 0"/>
  </joint>
  <gazebo reference="ensenso_frame">
    <sensor name="ensenso" type="depth">
      <always_on>true</always_on>
      <update_rate>20.0</update_rate>
      <camera>
        <horizontal_fov>1.04733333333</horizontal_fov>
        <image>
          <format>B8G8R8</format>
          <width>640</width>
          <height>480</height>
        </image>
        <clip>
          <near>0.001</near>
          <far>8.0</far>
        </clip>
      </camera>
      <plugin filename="libgazebo_ros_openni_kinect.so" name="kinect_camera_controller">
        <cameraName>ensenso</cameraName>
        <alwaysOn>true</alwaysOn>
        <updateRate>10</updateRate>
        <imageTopicName>rgb/image_raw</imageTopicName>
        <depthImageTopicName>depth/image_raw</depthImageTopicName>
        <pointCloudTopicName>/point_cloud</pointCloudTopicName>
        <cameraInfoTopicName>rgb/camera_info</cameraInfoTopicName>
        <depthImageCameraInfoTopicName>depth/camera_info</depthImageCameraInfoTopicName>
        <frameName>ensenso_optical_frame_sim</frameName>
        <baseline>0.1</baseline>
        <distortion_k1>0.0</distortion_k1>
        <distortion_k2>0.0</distortion_k2>
        <distortion_k3>0.0</distortion_k3>
        <distortion_t1>0.0</distortion_t1>
        <distortion_t2>0.0</distortion_t2>
        <pointCloudCutoff>0.1</pointCloudCutoff>
      </plugin>
    </sensor>
  </gazebo>
</robot>
